<?xml version="1.0" encoding="UTF-8"?>
<robot name="panda">
  
  <joint name="panda_finger_joint1" type="prismatic">
    <origin xyz="0. 0. 0.0584" rpy="0. 0. 1.5707964"/>
    <parent link="panda_panda_hand"/>
    <child link="panda_panda_leftfinger"/>
    <axis xyz="1. 0. 0."/>
    <limit lower="0." upper="0.04" effort="200." velocity="0.2"/>
  </joint>
  
  <joint name="panda_finger_joint2" type="prismatic">
    <origin xyz="0. 0. 0.0584" rpy="0. 0. -1.5707964"/>
    <parent link="panda_panda_hand"/>
    <child link="panda_panda_rightfinger"/>
    <axis xyz="1. 0. 0."/>
    <limit lower="0." upper="0.04" effort="200." velocity="0.2"/>
  </joint>
  
  <joint name="panda_hand_joint" type="fixed">
    <origin xyz="0.107 0. 0. " rpy="-1.5707964 0.7853981 -1.5707964"/>
    <parent link="panda_panda_link7"/>
    <child link="panda_panda_hand"/>
  </joint>
  
  <joint name="panda_joint1" type="revolute">
    <origin xyz="0. 0. 0.333" rpy="0. -1.5707963 0. "/>
    <parent link="panda_panda_link0"/>
    <child link="panda_panda_link1"/>
    <axis xyz="1. 0. 0."/>
    <limit lower="-2.8973001" upper="2.8973001" effort="87." velocity="2.1749999"/>
  </joint>
  
  <joint name="panda_joint2" type="revolute">
    <origin xyz="0. 0. 0." rpy="0. 0. 1.5707964"/>
    <parent link="panda_panda_link1"/>
    <child link="panda_panda_link2"/>
    <axis xyz="1. 0. 0."/>
    <limit lower="-1.7628" upper="1.7628" effort="87." velocity="2.1749999"/>
  </joint>
  
  <joint name="panda_joint3" type="revolute">
    <origin xyz="0. -0.316 0. " rpy="0. 0. -1.5707964"/>
    <parent link="panda_panda_link2"/>
    <child link="panda_panda_link3"/>
    <axis xyz="1. 0. 0."/>
    <limit lower="-2.8973001" upper="2.8973001" effort="87." velocity="2.1749999"/>
  </joint>
  
  <joint name="panda_joint4" type="revolute">
    <origin xyz="0. 0. -0.0825" rpy="0. 0. -1.5707964"/>
    <parent link="panda_panda_link3"/>
    <child link="panda_panda_link4"/>
    <axis xyz="1. 0. 0."/>
    <limit lower="-3.0718" upper="-0.0698" effort="87." velocity="2.1749999"/>
  </joint>
  
  <joint name="panda_joint5" type="revolute">
    <origin xyz="0. 0.384 0.0825" rpy="0. 0. 1.5707964"/>
    <parent link="panda_panda_link4"/>
    <child link="panda_panda_link5"/>
    <axis xyz="1. 0. 0."/>
    <limit lower="-2.8973001" upper="2.8973001" effort="12." velocity="2.6100004"/>
  </joint>
  
  <joint name="panda_joint6" type="revolute">
    <origin xyz="0. 0. 0." rpy="0. 0. -1.5707964"/>
    <parent link="panda_panda_link5"/>
    <child link="panda_panda_link6"/>
    <axis xyz="1. 0. 0."/>
    <limit lower="-0.0175" upper="3.7525" effort="12." velocity="2.6100004"/>
  </joint>
  
  <joint name="panda_joint7" type="revolute">
    <origin xyz="0. 0. -0.088" rpy="0. 0. -1.5707964"/>
    <parent link="panda_panda_link6"/>
    <child link="panda_panda_link7"/>
    <axis xyz="1. 0. 0."/>
    <limit lower="-2.8973001" upper="2.8973001" effort="12." velocity="2.6100004"/>
  </joint>
  
  <joint name="rootJoint" type="fixed">
    <origin xyz="0. 0. 0." rpy="0. 0. 0."/>
    <parent link="panda"/>
    <child link="panda_panda_link0"/>
  </joint>
  
  
  
  <link name="panda"/>
  <link name="panda_panda_hand">
    <visual>
      <origin xyz="0. 0. 0." rpy="0. 0. 0."/>
      <geometry>
        <mesh filename="package://ocs2_robotic_assets/resources/mobile_manipulator/franka/meshes/panda_panda_hand_visuals_panda_hand.obj" scale="0.01 0.01 0.01"/>
      </geometry>
    </visual>
    <visual>
      <origin xyz="0. 0. 0." rpy="0. 0. 0."/>
      <geometry>
        <mesh filename="package://ocs2_robotic_assets/resources/mobile_manipulator/franka/meshes/panda_panda_hand_collisions_collisions.obj" scale="1. 1. 1."/>
      </geometry>
    </visual>
    <collision>
      <origin xyz="0. 0. 0." rpy="0. 0. 0."/>
      <geometry>
        <mesh filename="package://ocs2_robotic_assets/resources/mobile_manipulator/franka/meshes/panda_panda_hand_collisions_collisions.obj" scale="1. 1. 1."/>
      </geometry>
    </collision>
  </link>
  <link name="panda_panda_leftfinger">
    <visual>
      <origin xyz="0. 0. 0." rpy="0. 0. -1.5707964"/>
      <geometry>
        <mesh filename="package://ocs2_robotic_assets/resources/mobile_manipulator/franka/meshes/panda_panda_leftfinger_visuals_panda_leftfinger.obj" scale="0.01 0.01 0.01"/>
      </geometry>
    </visual>
    <visual>
      <origin xyz="0. 0. 0." rpy="0. 0. -1.5707964"/>
      <geometry>
        <mesh filename="package://ocs2_robotic_assets/resources/mobile_manipulator/franka/meshes/panda_panda_leftfinger_collisions_collisions.obj" scale="1. 1. 1."/>
      </geometry>
    </visual>
    <collision>
      <origin xyz="0. 0. 0." rpy="0. 0. -1.5707964"/>
      <geometry>
        <mesh filename="package://ocs2_robotic_assets/resources/mobile_manipulator/franka/meshes/panda_panda_leftfinger_collisions_collisions.obj" scale="1. 1. 1."/>
      </geometry>
    </collision>
  </link>
  <link name="panda_panda_link0">
    <visual>
      <origin xyz="0. 0. 0." rpy="0. 0. 0."/>
      <geometry>
        <mesh filename="package://ocs2_robotic_assets/resources/mobile_manipulator/franka/meshes/panda_panda_link0_visuals_panda_link0.obj" scale="0.01 0.01 0.01"/>
      </geometry>
    </visual>
    <visual>
      <origin xyz="0. 0. 0." rpy="0. 0. 0."/>
      <geometry>
        <mesh filename="package://ocs2_robotic_assets/resources/mobile_manipulator/franka/meshes/panda_panda_link0_collisions_collisions.obj" scale="1. 1. 1."/>
      </geometry>
    </visual>
    <collision>
      <origin xyz="0. 0. 0." rpy="0. 0. 0."/>
      <geometry>
        <mesh filename="package://ocs2_robotic_assets/resources/mobile_manipulator/franka/meshes/panda_panda_link0_collisions_collisions.obj" scale="1. 1. 1."/>
      </geometry>
    </collision>
  </link>
  <link name="panda_panda_link1">
    <visual>
      <origin xyz="0. 0. 0." rpy="0. 1.5707963 0. "/>
      <geometry>
        <mesh filename="package://ocs2_robotic_assets/resources/mobile_manipulator/franka/meshes/panda_panda_link1_visuals_panda_link1.obj" scale="0.01 0.01 0.01"/>
      </geometry>
    </visual>
    <visual>
      <origin xyz="0. 0. 0." rpy="0. 1.5707963 0. "/>
      <geometry>
        <mesh filename="package://ocs2_robotic_assets/resources/mobile_manipulator/franka/meshes/panda_panda_link1_collisions_collisions.obj" scale="1. 1. 1."/>
      </geometry>
    </visual>
    <collision>
      <origin xyz="0. 0. 0." rpy="0. 1.5707963 0. "/>
      <geometry>
        <mesh filename="package://ocs2_robotic_assets/resources/mobile_manipulator/franka/meshes/panda_panda_link1_collisions_collisions.obj" scale="1. 1. 1."/>
      </geometry>
    </collision>
  </link>
  <link name="panda_panda_link2">
    <visual>
      <origin xyz="0. 0. 0." rpy="0. 1.5707963 0. "/>
      <geometry>
        <mesh filename="package://ocs2_robotic_assets/resources/mobile_manipulator/franka/meshes/panda_panda_link2_visuals_panda_link2.obj" scale="0.01 0.01 0.01"/>
      </geometry>
    </visual>
    <visual>
      <origin xyz="0. 0. 0." rpy="0. 1.5707963 0. "/>
      <geometry>
        <mesh filename="package://ocs2_robotic_assets/resources/mobile_manipulator/franka/meshes/panda_panda_link2_collisions_collisions.obj" scale="1. 1. 1."/>
      </geometry>
    </visual>
    <collision>
      <origin xyz="0. 0. 0." rpy="0. 1.5707963 0. "/>
      <geometry>
        <mesh filename="package://ocs2_robotic_assets/resources/mobile_manipulator/franka/meshes/panda_panda_link2_collisions_collisions.obj" scale="1. 1. 1."/>
      </geometry>
    </collision>
  </link>
  <link name="panda_panda_link3">
    <visual>
      <origin xyz="0. 0. 0." rpy="0. 1.5707963 0. "/>
      <geometry>
        <mesh filename="package://ocs2_robotic_assets/resources/mobile_manipulator/franka/meshes/panda_panda_link3_visuals_panda_link3.obj" scale="0.01 0.01 0.01"/>
      </geometry>
    </visual>
    <visual>
      <origin xyz="0. 0. 0." rpy="0. 1.5707963 0. "/>
      <geometry>
        <mesh filename="package://ocs2_robotic_assets/resources/mobile_manipulator/franka/meshes/panda_panda_link3_collisions_collisions.obj" scale="1. 1. 1."/>
      </geometry>
    </visual>
    <collision>
      <origin xyz="0. 0. 0." rpy="0. 1.5707963 0. "/>
      <geometry>
        <mesh filename="package://ocs2_robotic_assets/resources/mobile_manipulator/franka/meshes/panda_panda_link3_collisions_collisions.obj" scale="1. 1. 1."/>
      </geometry>
    </collision>
  </link>
  <link name="panda_panda_link4">
    <visual>
      <origin xyz="0. 0. 0." rpy="0. 1.5707963 0. "/>
      <geometry>
        <mesh filename="package://ocs2_robotic_assets/resources/mobile_manipulator/franka/meshes/panda_panda_link4_visuals_panda_link4.obj" scale="0.01 0.01 0.01"/>
      </geometry>
    </visual>
    <visual>
      <origin xyz="0. 0. 0." rpy="0. 1.5707963 0. "/>
      <geometry>
        <mesh filename="package://ocs2_robotic_assets/resources/mobile_manipulator/franka/meshes/panda_panda_link4_collisions_collisions.obj" scale="1. 1. 1."/>
      </geometry>
    </visual>
    <collision>
      <origin xyz="0. 0. 0." rpy="0. 1.5707963 0. "/>
      <geometry>
        <mesh filename="package://ocs2_robotic_assets/resources/mobile_manipulator/franka/meshes/panda_panda_link4_collisions_collisions.obj" scale="1. 1. 1."/>
      </geometry>
    </collision>
  </link>
  <link name="panda_panda_link5">
    <visual>
      <origin xyz="0. 0. 0." rpy="0. 1.5707963 0. "/>
      <geometry>
        <mesh filename="package://ocs2_robotic_assets/resources/mobile_manipulator/franka/meshes/panda_panda_link5_visuals_panda_link5.obj" scale="0.01 0.01 0.01"/>
      </geometry>
    </visual>
    <visual>
      <origin xyz="0. 0. 0." rpy="0. 1.5707963 0. "/>
      <geometry>
        <mesh filename="package://ocs2_robotic_assets/resources/mobile_manipulator/franka/meshes/panda_panda_link5_collisions_collisions.obj" scale="1. 1. 1."/>
      </geometry>
    </visual>
    <collision>
      <origin xyz="0. 0. 0." rpy="0. 1.5707963 0. "/>
      <geometry>
        <mesh filename="package://ocs2_robotic_assets/resources/mobile_manipulator/franka/meshes/panda_panda_link5_collisions_collisions.obj" scale="1. 1. 1."/>
      </geometry>
    </collision>
  </link>
  <link name="panda_panda_link6">
    <visual>
      <origin xyz="0. 0. 0." rpy="0. 1.5707963 0. "/>
      <geometry>
        <mesh filename="package://ocs2_robotic_assets/resources/mobile_manipulator/franka/meshes/panda_panda_link6_visuals_panda_link6.obj" scale="0.01 0.01 0.01"/>
      </geometry>
    </visual>
    <visual>
      <origin xyz="0. 0. 0." rpy="0. 1.5707963 0. "/>
      <geometry>
        <mesh filename="package://ocs2_robotic_assets/resources/mobile_manipulator/franka/meshes/panda_panda_link6_collisions_collisions.obj" scale="1. 1. 1."/>
      </geometry>
    </visual>
    <collision>
      <origin xyz="0. 0. 0." rpy="0. 1.5707963 0. "/>
      <geometry>
        <mesh filename="package://ocs2_robotic_assets/resources/mobile_manipulator/franka/meshes/panda_panda_link6_collisions_collisions.obj" scale="1. 1. 1."/>
      </geometry>
    </collision>
  </link>
  <link name="panda_panda_link7">
    <visual>
      <origin xyz="0. 0. 0." rpy="0. 1.5707963 0. "/>
      <geometry>
        <mesh filename="package://ocs2_robotic_assets/resources/mobile_manipulator/franka/meshes/panda_panda_link7_visuals_panda_link7.obj" scale="0.01 0.01 0.01"/>
      </geometry>
    </visual>
    <visual>
      <origin xyz="0. 0. 0." rpy="0. 1.5707963 0. "/>
      <geometry>
        <mesh filename="package://ocs2_robotic_assets/resources/mobile_manipulator/franka/meshes/panda_panda_link7_collisions_collisions.obj" scale="1. 1. 1."/>
      </geometry>
    </visual>
    <collision>
      <origin xyz="0. 0. 0." rpy="0. 1.5707963 0. "/>
      <geometry>
        <mesh filename="package://ocs2_robotic_assets/resources/mobile_manipulator/franka/meshes/panda_panda_link7_collisions_collisions.obj" scale="1. 1. 1."/>
      </geometry>
    </collision>
  </link>
  <link name="panda_panda_rightfinger">
    <visual>
      <origin xyz="0. 0. 0." rpy="0. 0. 1.5707964"/>
      <geometry>
        <mesh filename="package://ocs2_robotic_assets/resources/mobile_manipulator/franka/meshes/panda_panda_rightfinger_visuals_panda_rightfinger.obj" scale="0.01 0.01 0.01"/>
      </geometry>
    </visual>
    <visual>
      <origin xyz="0. 0. 0." rpy="0. 0. -1.5707963"/>
      <geometry>
        <mesh filename="package://ocs2_robotic_assets/resources/mobile_manipulator/franka/meshes/panda_panda_rightfinger_collisions_collisions.obj" scale="1. 1. 1."/>
      </geometry>
    </visual>
    <collision>
      <origin xyz="0. 0. 0." rpy="0. 0. -1.5707963"/>
      <geometry>
        <mesh filename="package://ocs2_robotic_assets/resources/mobile_manipulator/franka/meshes/panda_panda_rightfinger_collisions_collisions.obj" scale="1. 1. 1."/>
      </geometry>
    </collision>
  </link>
</robot>
